(dp1
S'output'
p2
S"<type 'exceptions.AttributeError'> 'DAL' object has no attribute 'person'"
p3
sS'layer'
p4
S'/home/topf/Web2Py/web2py/applications/Asylum/controllers/asylum.py'
p5
sS'code'
p6
S'<code object <module> at 0xae8319b0, file "/home/topf/Web2Py/web2py/applications/Asylum/controllers/asylum.py", line 3>'
p7
sS'snapshot'
p8
(dp9
sS'traceback'
p10
S'Traceback (most recent call last):\n  File "/home/topf/Web2Py/web2py/gluon/restricted.py", line 219, in restricted\n    exec(ccode, environment)\n  File "/home/topf/Web2Py/web2py/applications/Asylum/controllers/asylum.py", line 105, in <module>\n  File "/home/topf/Web2Py/web2py/gluon/globals.py", line 409, in <lambda>\n    self._caller = lambda f: f()\n  File "/home/topf/Web2Py/web2py/applications/Asylum/controllers/asylum.py", line 85, in update_pbase\n    record = db.person(request.args(0)) or redirect(URL(\'show_pbase\'))\n  File "/home/topf/Web2Py/web2py/gluon/packages/dal/pydal/base.py", line 670, in __getattr__\n    return BasicStorage.__getattribute__(self, key)\nAttributeError: \'DAL\' object has no attribute \'person\'\n'
p11
s.